2022-02-12 12:39:56,240 INFO    MainThread:89335 [wandb_setup.py:_flush():69] setting env: {'project': 'telco_churn', 'run_group': 'development'}
2022-02-12 12:39:56,242 INFO    MainThread:89335 [wandb_setup.py:_flush():69] setting login settings: {}
2022-02-12 12:39:56,243 INFO    MainThread:89335 [wandb_init.py:_log_setup():336] Logging user logs to /Users/jelaleddin/MLPipeline-TelcoCustomerChurn/components/get_data/wandb/run-20220212_123956-2sfk8kly/logs/debug.log
2022-02-12 12:39:56,243 INFO    MainThread:89335 [wandb_init.py:_log_setup():337] Logging internal logs to /Users/jelaleddin/MLPipeline-TelcoCustomerChurn/components/get_data/wandb/run-20220212_123956-2sfk8kly/logs/debug-internal.log
2022-02-12 12:39:56,243 INFO    MainThread:89335 [wandb_init.py:init():369] calling init triggers
2022-02-12 12:39:56,243 INFO    MainThread:89335 [wandb_init.py:init():374] wandb.init called with sweep_config: {}
config: {}
2022-02-12 12:39:56,243 INFO    MainThread:89335 [wandb_init.py:init():418] starting backend
2022-02-12 12:39:56,243 INFO    MainThread:89335 [backend.py:_multiprocessing_setup():70] multiprocessing start_methods=spawn,fork,forkserver, using: spawn
2022-02-12 12:39:56,260 INFO    MainThread:89335 [backend.py:ensure_launched():132] starting backend process...
2022-02-12 12:39:56,267 INFO    MainThread:89335 [backend.py:ensure_launched():136] started backend process with pid: 89343
2022-02-12 12:39:56,270 INFO    MainThread:89335 [wandb_init.py:init():423] backend started and connected
2022-02-12 12:39:56,274 INFO    MainThread:89335 [wandb_init.py:init():465] updated telemetry
2022-02-12 12:39:56,275 INFO    MainThread:89335 [wandb_init.py:init():484] communicating current version
2022-02-12 12:40:01,277 INFO    MainThread:89335 [wandb_init.py:init():497] communicating run to backend with 30 second timeout
2022-02-12 12:40:31,282 INFO    MainThread:89335 [interface.py:_communicate_run():657] couldn't get run from backend
2022-02-12 12:40:31,282 ERROR   MainThread:89335 [wandb_init.py:init():501] backend process timed out
2022-02-12 12:40:31,282 ERROR   MainThread:89335 [wandb_init.py:init():510] encountered error: Error communicating with wandb process
try: wandb.init(settings=wandb.Settings(start_method='fork'))
or:  wandb.init(settings=wandb.Settings(start_method='thread'))
For more info see: https://docs.wandb.ai/library/init#init-start-error
2022-02-12 12:41:22,259 INFO    MainThread:89335 [wandb_init.py:teardown():187] tearing down wandb.init
