2022-02-12 12:39:56,903 INFO    MainThread:89343 [internal.py:wandb_internal():88] W&B internal server running at pid: 89343, started at: 2022-02-12 12:39:56.903019
2022-02-12 12:39:56,904 DEBUG   HandlerThread:89343 [handler.py:handle_request():124] handle_request: check_version
2022-02-12 12:39:56,905 INFO    WriterThread:89343 [datastore.py:open_for_write():77] open: /Users/jelaleddin/MLPipeline-TelcoCustomerChurn/components/get_data/wandb/run-20220212_123956-2sfk8kly/run-2sfk8kly.wandb
2022-02-12 12:39:56,906 DEBUG   SenderThread:89343 [sender.py:send():179] send: header
2022-02-12 12:39:56,907 DEBUG   SenderThread:89343 [sender.py:send_request():193] send_request: check_version
2022-02-12 12:40:01,911 DEBUG   SenderThread:89343 [sender.py:send():179] send: run
2022-02-12 12:40:31,283 DEBUG   HandlerThread:89343 [handler.py:handle_request():124] handle_request: shutdown
2022-02-12 12:40:31,283 INFO    HandlerThread:89343 [handler.py:finish():638] shutting down handler
2022-02-12 12:40:31,369 INFO    WriterThread:89343 [datastore.py:close():258] close: /Users/jelaleddin/MLPipeline-TelcoCustomerChurn/components/get_data/wandb/run-20220212_123956-2sfk8kly/run-2sfk8kly.wandb
2022-02-12 12:41:09,492 INFO    SenderThread:89343 [dir_watcher.py:__init__():168] watching files in: /Users/jelaleddin/MLPipeline-TelcoCustomerChurn/components/get_data/wandb/run-20220212_123956-2sfk8kly/files
2022-02-12 12:41:09,493 INFO    SenderThread:89343 [sender.py:_start_run_threads():704] run started: 2sfk8kly with start time 1644651596
2022-02-12 12:41:09,493 INFO    SenderThread:89343 [sender.py:finish():933] shutting down sender
2022-02-12 12:41:09,493 INFO    SenderThread:89343 [dir_watcher.py:finish():282] shutting down directory watcher
2022-02-12 12:41:10,495 INFO    SenderThread:89343 [dir_watcher.py:finish():312] scan: /Users/jelaleddin/MLPipeline-TelcoCustomerChurn/components/get_data/wandb/run-20220212_123956-2sfk8kly/files
2022-02-12 12:41:10,498 INFO    SenderThread:89343 [dir_watcher.py:finish():318] scan save: /Users/jelaleddin/MLPipeline-TelcoCustomerChurn/components/get_data/wandb/run-20220212_123956-2sfk8kly/files/config.yaml config.yaml
2022-02-12 12:41:10,499 INFO    SenderThread:89343 [file_pusher.py:finish():176] shutting down file pusher
2022-02-12 12:41:10,499 INFO    SenderThread:89343 [file_pusher.py:join():181] waiting for file pusher
2022-02-12 12:41:11,301 ERROR   Thread-10 :89343 [internal_api.py:upload_file():1121] upload_file exception https://storage.googleapis.com/wandb-production.appspot.com/jelal/telco_churn/2sfk8kly/config.yaml?Expires=1644738071&GoogleAccessId=wandb-production%40appspot.gserviceaccount.com&Signature=YBfoqmiewe0%2BSOYZWOxV3sI%2F6mrz%2BCsHG9DDrclSAbuw%2By603Ou66OKVbPZwzOiQ9QQOk8hhsQS2lXYPIc4ozHua%2BT8w0jxCF0CQZ%2BQ4n5mrw8csbzBYDQT%2B7BMO4D1OQ94z%2FwC6MhmdePDjUtmy9Zy8W4hV0T6nCKJVlJU9xCpKgDSzdEL61%2FquptHo%2BihKQQT1jYqI5eSsh8hIhzxTuEfzjo74L%2F6ImLLpc8m9BnO0FtQI2pXmzQmCUENZoCWLgMV3R0C4zRbOi3aVMcl8wcwn4170IM1oKDnU5IrsxztFyhCzJ%2FF3sJGfWKs0Eodchj%2BS6ZH6MxU5lAqc4tnaQg%3D%3D ('Connection aborted.', ConnectionResetError(54, 'Connection reset by peer'))
2022-02-12 12:41:12,565 ERROR   Thread-10 :89343 [internal_api.py:upload_file():1121] upload_file exception https://storage.googleapis.com/wandb-production.appspot.com/jelal/telco_churn/2sfk8kly/config.yaml?Expires=1644738071&GoogleAccessId=wandb-production%40appspot.gserviceaccount.com&Signature=YBfoqmiewe0%2BSOYZWOxV3sI%2F6mrz%2BCsHG9DDrclSAbuw%2By603Ou66OKVbPZwzOiQ9QQOk8hhsQS2lXYPIc4ozHua%2BT8w0jxCF0CQZ%2BQ4n5mrw8csbzBYDQT%2B7BMO4D1OQ94z%2FwC6MhmdePDjUtmy9Zy8W4hV0T6nCKJVlJU9xCpKgDSzdEL61%2FquptHo%2BihKQQT1jYqI5eSsh8hIhzxTuEfzjo74L%2F6ImLLpc8m9BnO0FtQI2pXmzQmCUENZoCWLgMV3R0C4zRbOi3aVMcl8wcwn4170IM1oKDnU5IrsxztFyhCzJ%2FF3sJGfWKs0Eodchj%2BS6ZH6MxU5lAqc4tnaQg%3D%3D ('Connection aborted.', ConnectionResetError(54, 'Connection reset by peer'))
2022-02-12 12:41:14,798 ERROR   Thread-10 :89343 [internal_api.py:upload_file():1121] upload_file exception https://storage.googleapis.com/wandb-production.appspot.com/jelal/telco_churn/2sfk8kly/config.yaml?Expires=1644738071&GoogleAccessId=wandb-production%40appspot.gserviceaccount.com&Signature=YBfoqmiewe0%2BSOYZWOxV3sI%2F6mrz%2BCsHG9DDrclSAbuw%2By603Ou66OKVbPZwzOiQ9QQOk8hhsQS2lXYPIc4ozHua%2BT8w0jxCF0CQZ%2BQ4n5mrw8csbzBYDQT%2B7BMO4D1OQ94z%2FwC6MhmdePDjUtmy9Zy8W4hV0T6nCKJVlJU9xCpKgDSzdEL61%2FquptHo%2BihKQQT1jYqI5eSsh8hIhzxTuEfzjo74L%2F6ImLLpc8m9BnO0FtQI2pXmzQmCUENZoCWLgMV3R0C4zRbOi3aVMcl8wcwn4170IM1oKDnU5IrsxztFyhCzJ%2FF3sJGfWKs0Eodchj%2BS6ZH6MxU5lAqc4tnaQg%3D%3D ('Connection aborted.', ConnectionResetError(54, 'Connection reset by peer'))
2022-02-12 12:41:14,799 ERROR   Thread-10 :89343 [retry.py:__call__():126] Retry attempt failed:
Traceback (most recent call last):
  File "/Users/jelaleddin/anaconda3/envs/mlflow-5db43bd27a8446422da9c67a9329d4bf1343e076/lib/python3.9/site-packages/urllib3/connectionpool.py", line 670, in urlopen
    httplib_response = self._make_request(
  File "/Users/jelaleddin/anaconda3/envs/mlflow-5db43bd27a8446422da9c67a9329d4bf1343e076/lib/python3.9/site-packages/urllib3/connectionpool.py", line 381, in _make_request
    self._validate_conn(conn)
  File "/Users/jelaleddin/anaconda3/envs/mlflow-5db43bd27a8446422da9c67a9329d4bf1343e076/lib/python3.9/site-packages/urllib3/connectionpool.py", line 978, in _validate_conn
    conn.connect()
  File "/Users/jelaleddin/anaconda3/envs/mlflow-5db43bd27a8446422da9c67a9329d4bf1343e076/lib/python3.9/site-packages/urllib3/connection.py", line 362, in connect
    self.sock = ssl_wrap_socket(
  File "/Users/jelaleddin/anaconda3/envs/mlflow-5db43bd27a8446422da9c67a9329d4bf1343e076/lib/python3.9/site-packages/urllib3/util/ssl_.py", line 386, in ssl_wrap_socket
    return context.wrap_socket(sock, server_hostname=server_hostname)
  File "/Users/jelaleddin/anaconda3/envs/mlflow-5db43bd27a8446422da9c67a9329d4bf1343e076/lib/python3.9/ssl.py", line 500, in wrap_socket
    return self.sslsocket_class._create(
  File "/Users/jelaleddin/anaconda3/envs/mlflow-5db43bd27a8446422da9c67a9329d4bf1343e076/lib/python3.9/ssl.py", line 1040, in _create
    self.do_handshake()
  File "/Users/jelaleddin/anaconda3/envs/mlflow-5db43bd27a8446422da9c67a9329d4bf1343e076/lib/python3.9/ssl.py", line 1309, in do_handshake
    self._sslobj.do_handshake()
ConnectionResetError: [Errno 54] Connection reset by peer

During handling of the above exception, another exception occurred:

Traceback (most recent call last):
  File "/Users/jelaleddin/anaconda3/envs/mlflow-5db43bd27a8446422da9c67a9329d4bf1343e076/lib/python3.9/site-packages/requests/adapters.py", line 439, in send
    resp = conn.urlopen(
  File "/Users/jelaleddin/anaconda3/envs/mlflow-5db43bd27a8446422da9c67a9329d4bf1343e076/lib/python3.9/site-packages/urllib3/connectionpool.py", line 726, in urlopen
    retries = retries.increment(
  File "/Users/jelaleddin/anaconda3/envs/mlflow-5db43bd27a8446422da9c67a9329d4bf1343e076/lib/python3.9/site-packages/urllib3/util/retry.py", line 410, in increment
    raise six.reraise(type(error), error, _stacktrace)
  File "/Users/jelaleddin/anaconda3/envs/mlflow-5db43bd27a8446422da9c67a9329d4bf1343e076/lib/python3.9/site-packages/urllib3/packages/six.py", line 734, in reraise
    raise value.with_traceback(tb)
  File "/Users/jelaleddin/anaconda3/envs/mlflow-5db43bd27a8446422da9c67a9329d4bf1343e076/lib/python3.9/site-packages/urllib3/connectionpool.py", line 670, in urlopen
    httplib_response = self._make_request(
  File "/Users/jelaleddin/anaconda3/envs/mlflow-5db43bd27a8446422da9c67a9329d4bf1343e076/lib/python3.9/site-packages/urllib3/connectionpool.py", line 381, in _make_request
    self._validate_conn(conn)
  File "/Users/jelaleddin/anaconda3/envs/mlflow-5db43bd27a8446422da9c67a9329d4bf1343e076/lib/python3.9/site-packages/urllib3/connectionpool.py", line 978, in _validate_conn
    conn.connect()
  File "/Users/jelaleddin/anaconda3/envs/mlflow-5db43bd27a8446422da9c67a9329d4bf1343e076/lib/python3.9/site-packages/urllib3/connection.py", line 362, in connect
    self.sock = ssl_wrap_socket(
  File "/Users/jelaleddin/anaconda3/envs/mlflow-5db43bd27a8446422da9c67a9329d4bf1343e076/lib/python3.9/site-packages/urllib3/util/ssl_.py", line 386, in ssl_wrap_socket
    return context.wrap_socket(sock, server_hostname=server_hostname)
  File "/Users/jelaleddin/anaconda3/envs/mlflow-5db43bd27a8446422da9c67a9329d4bf1343e076/lib/python3.9/ssl.py", line 500, in wrap_socket
    return self.sslsocket_class._create(
  File "/Users/jelaleddin/anaconda3/envs/mlflow-5db43bd27a8446422da9c67a9329d4bf1343e076/lib/python3.9/ssl.py", line 1040, in _create
    self.do_handshake()
  File "/Users/jelaleddin/anaconda3/envs/mlflow-5db43bd27a8446422da9c67a9329d4bf1343e076/lib/python3.9/ssl.py", line 1309, in do_handshake
    self._sslobj.do_handshake()
urllib3.exceptions.ProtocolError: ('Connection aborted.', ConnectionResetError(54, 'Connection reset by peer'))

During handling of the above exception, another exception occurred:

Traceback (most recent call last):
  File "/Users/jelaleddin/anaconda3/envs/mlflow-5db43bd27a8446422da9c67a9329d4bf1343e076/lib/python3.9/site-packages/wandb/sdk/internal/internal_api.py", line 1118, in upload_file
    response = requests.put(url, data=progress, headers=extra_headers)
  File "/Users/jelaleddin/anaconda3/envs/mlflow-5db43bd27a8446422da9c67a9329d4bf1343e076/lib/python3.9/site-packages/requests/api.py", line 134, in put
    return request('put', url, data=data, **kwargs)
  File "/Users/jelaleddin/anaconda3/envs/mlflow-5db43bd27a8446422da9c67a9329d4bf1343e076/lib/python3.9/site-packages/requests/api.py", line 61, in request
    return session.request(method=method, url=url, **kwargs)
  File "/Users/jelaleddin/anaconda3/envs/mlflow-5db43bd27a8446422da9c67a9329d4bf1343e076/lib/python3.9/site-packages/requests/sessions.py", line 530, in request
    resp = self.send(prep, **send_kwargs)
  File "/Users/jelaleddin/anaconda3/envs/mlflow-5db43bd27a8446422da9c67a9329d4bf1343e076/lib/python3.9/site-packages/requests/sessions.py", line 643, in send
    r = adapter.send(request, **kwargs)
  File "/Users/jelaleddin/anaconda3/envs/mlflow-5db43bd27a8446422da9c67a9329d4bf1343e076/lib/python3.9/site-packages/requests/adapters.py", line 498, in send
    raise ConnectionError(err, request=request)
requests.exceptions.ConnectionError: ('Connection aborted.', ConnectionResetError(54, 'Connection reset by peer'))

During handling of the above exception, another exception occurred:

Traceback (most recent call last):
  File "/Users/jelaleddin/anaconda3/envs/mlflow-5db43bd27a8446422da9c67a9329d4bf1343e076/lib/python3.9/site-packages/wandb/sdk/lib/retry.py", line 102, in __call__
    result = self._call_fn(*args, **kwargs)
  File "/Users/jelaleddin/anaconda3/envs/mlflow-5db43bd27a8446422da9c67a9329d4bf1343e076/lib/python3.9/site-packages/wandb/sdk/internal/internal_api.py", line 1129, in upload_file
    util.sentry_reraise(retry.TransientException(exc=e))
  File "/Users/jelaleddin/anaconda3/envs/mlflow-5db43bd27a8446422da9c67a9329d4bf1343e076/lib/python3.9/site-packages/wandb/util.py", line 121, in sentry_reraise
    six.reraise(type(exc), exc, sys.exc_info()[2])
  File "/Users/jelaleddin/anaconda3/envs/mlflow-5db43bd27a8446422da9c67a9329d4bf1343e076/lib/python3.9/site-packages/six.py", line 718, in reraise
    raise value.with_traceback(tb)
  File "/Users/jelaleddin/anaconda3/envs/mlflow-5db43bd27a8446422da9c67a9329d4bf1343e076/lib/python3.9/site-packages/wandb/sdk/internal/internal_api.py", line 1118, in upload_file
    response = requests.put(url, data=progress, headers=extra_headers)
  File "/Users/jelaleddin/anaconda3/envs/mlflow-5db43bd27a8446422da9c67a9329d4bf1343e076/lib/python3.9/site-packages/requests/api.py", line 134, in put
    return request('put', url, data=data, **kwargs)
  File "/Users/jelaleddin/anaconda3/envs/mlflow-5db43bd27a8446422da9c67a9329d4bf1343e076/lib/python3.9/site-packages/requests/api.py", line 61, in request
    return session.request(method=method, url=url, **kwargs)
  File "/Users/jelaleddin/anaconda3/envs/mlflow-5db43bd27a8446422da9c67a9329d4bf1343e076/lib/python3.9/site-packages/requests/sessions.py", line 530, in request
    resp = self.send(prep, **send_kwargs)
  File "/Users/jelaleddin/anaconda3/envs/mlflow-5db43bd27a8446422da9c67a9329d4bf1343e076/lib/python3.9/site-packages/requests/sessions.py", line 643, in send
    r = adapter.send(request, **kwargs)
  File "/Users/jelaleddin/anaconda3/envs/mlflow-5db43bd27a8446422da9c67a9329d4bf1343e076/lib/python3.9/site-packages/requests/adapters.py", line 498, in send
    raise ConnectionError(err, request=request)
wandb.sdk.lib.retry.TransientException: None
2022-02-12 12:41:20,771 INFO    Thread-10 :89343 [upload_job.py:push():133] Uploaded file /Users/jelaleddin/MLPipeline-TelcoCustomerChurn/components/get_data/wandb/run-20220212_123956-2sfk8kly/files/config.yaml
2022-02-12 12:41:21,947 INFO    MainThread:89343 [internal.py:handle_exit():78] Internal process exited
