2022-02-24 15:09:57,596 INFO    MainThread:28593 [internal.py:wandb_internal():88] W&B internal server running at pid: 28593, started at: 2022-02-24 15:09:57.596557
2022-02-24 15:09:57,598 INFO    WriterThread:28593 [datastore.py:open_for_write():77] open: /Users/jelaleddin/MLPipeline-TelcoCustomerChurn/components/check_data/wandb/run-20220224_150956-376tdk7x/run-376tdk7x.wandb
2022-02-24 15:09:57,598 DEBUG   HandlerThread:28593 [handler.py:handle_request():101] handle_request: check_version
2022-02-24 15:09:57,599 DEBUG   SenderThread:28593 [sender.py:send():122] send: header
2022-02-24 15:09:57,599 DEBUG   SenderThread:28593 [sender.py:send():122] send: request
2022-02-24 15:09:57,599 DEBUG   SenderThread:28593 [sender.py:send_request():131] send_request: check_version
2022-02-24 15:10:02,605 DEBUG   SenderThread:28593 [sender.py:send():122] send: run
2022-02-24 15:10:02,608 INFO    SenderThread:28593 [sender.py:_maybe_setup_resume():312] checking resume status for None/telco_churn/376tdk7x
2022-02-24 15:10:31,974 DEBUG   HandlerThread:28593 [handler.py:handle_request():101] handle_request: shutdown
2022-02-24 15:10:31,974 INFO    HandlerThread:28593 [handler.py:finish():535] shutting down handler
2022-02-24 15:10:32,062 INFO    WriterThread:28593 [datastore.py:close():258] close: /Users/jelaleddin/MLPipeline-TelcoCustomerChurn/components/check_data/wandb/run-20220224_150956-376tdk7x/run-376tdk7x.wandb
2022-02-24 15:11:35,997 INFO    SenderThread:28593 [sender.py:_start_run_threads():596] run started: 376tdk7x with start time 1645697396
2022-02-24 15:11:36,000 INFO    SenderThread:28593 [sender.py:finish():833] shutting down sender
2022-02-24 15:11:37,813 ERROR   Thread-10 :28593 [internal_api.py:upload_file():1201] upload_file exception https://storage.googleapis.com/wandb-production.appspot.com/jelal/telco_churn/376tdk7x/config.yaml?Expires=1645783897&GoogleAccessId=wandb-production%40appspot.gserviceaccount.com&Signature=jtSgfvx%2B2hwQ%2Bl7cRCFeB0%2BpKbZubUSwPXdKVdWnZj8IpJuK5gGmtCcb2l1N5qDXq6ivj8M7qw%2BNNS%2BRl8MIo%2F0DQbx31w%2FvI0SRzeZEtVWDRtH39JxIz4xha%2FLnmAoIw6aCI8SgMumjJ0Ex1gFBpeDT6kKFwS8NTYrPBLOpX0amnKorQ4clgOZrZKKlz4w3ZKAnjDDFKkjQHHzkHDju3M1ttZGGS0vA%2FJyyY%2FISe607lPqqvl0j%2B%2B4NQ3S8DmfSeNQ5gdRF5D7KpauhpSjQWxj36CCzCk7nes3WM7cfG%2FJNeOnNP378WyFgynW2Fl74r3L29sKNq0BHyRGaqZAwHw%3D%3D ('Connection aborted.', ConnectionResetError(54, 'Connection reset by peer'))
2022-02-24 15:11:39,178 ERROR   Thread-10 :28593 [internal_api.py:upload_file():1201] upload_file exception https://storage.googleapis.com/wandb-production.appspot.com/jelal/telco_churn/376tdk7x/config.yaml?Expires=1645783897&GoogleAccessId=wandb-production%40appspot.gserviceaccount.com&Signature=jtSgfvx%2B2hwQ%2Bl7cRCFeB0%2BpKbZubUSwPXdKVdWnZj8IpJuK5gGmtCcb2l1N5qDXq6ivj8M7qw%2BNNS%2BRl8MIo%2F0DQbx31w%2FvI0SRzeZEtVWDRtH39JxIz4xha%2FLnmAoIw6aCI8SgMumjJ0Ex1gFBpeDT6kKFwS8NTYrPBLOpX0amnKorQ4clgOZrZKKlz4w3ZKAnjDDFKkjQHHzkHDju3M1ttZGGS0vA%2FJyyY%2FISe607lPqqvl0j%2B%2B4NQ3S8DmfSeNQ5gdRF5D7KpauhpSjQWxj36CCzCk7nes3WM7cfG%2FJNeOnNP378WyFgynW2Fl74r3L29sKNq0BHyRGaqZAwHw%3D%3D ('Connection aborted.', ConnectionResetError(54, 'Connection reset by peer'))
2022-02-24 15:11:41,821 ERROR   Thread-10 :28593 [internal_api.py:upload_file():1201] upload_file exception https://storage.googleapis.com/wandb-production.appspot.com/jelal/telco_churn/376tdk7x/config.yaml?Expires=1645783897&GoogleAccessId=wandb-production%40appspot.gserviceaccount.com&Signature=jtSgfvx%2B2hwQ%2Bl7cRCFeB0%2BpKbZubUSwPXdKVdWnZj8IpJuK5gGmtCcb2l1N5qDXq6ivj8M7qw%2BNNS%2BRl8MIo%2F0DQbx31w%2FvI0SRzeZEtVWDRtH39JxIz4xha%2FLnmAoIw6aCI8SgMumjJ0Ex1gFBpeDT6kKFwS8NTYrPBLOpX0amnKorQ4clgOZrZKKlz4w3ZKAnjDDFKkjQHHzkHDju3M1ttZGGS0vA%2FJyyY%2FISe607lPqqvl0j%2B%2B4NQ3S8DmfSeNQ5gdRF5D7KpauhpSjQWxj36CCzCk7nes3WM7cfG%2FJNeOnNP378WyFgynW2Fl74r3L29sKNq0BHyRGaqZAwHw%3D%3D ('Connection aborted.', ConnectionResetError(54, 'Connection reset by peer'))
2022-02-24 15:11:41,822 ERROR   Thread-10 :28593 [retry.py:__call__():111] Retry attempt failed:
Traceback (most recent call last):
  File "/Users/jelaleddin/anaconda3/envs/mlflow-d1fd4b13aac386abe6aa5a2ada1ca11214902ce4/lib/python3.9/site-packages/urllib3/connectionpool.py", line 703, in urlopen
    httplib_response = self._make_request(
  File "/Users/jelaleddin/anaconda3/envs/mlflow-d1fd4b13aac386abe6aa5a2ada1ca11214902ce4/lib/python3.9/site-packages/urllib3/connectionpool.py", line 386, in _make_request
    self._validate_conn(conn)
  File "/Users/jelaleddin/anaconda3/envs/mlflow-d1fd4b13aac386abe6aa5a2ada1ca11214902ce4/lib/python3.9/site-packages/urllib3/connectionpool.py", line 1040, in _validate_conn
    conn.connect()
  File "/Users/jelaleddin/anaconda3/envs/mlflow-d1fd4b13aac386abe6aa5a2ada1ca11214902ce4/lib/python3.9/site-packages/urllib3/connection.py", line 416, in connect
    self.sock = ssl_wrap_socket(
  File "/Users/jelaleddin/anaconda3/envs/mlflow-d1fd4b13aac386abe6aa5a2ada1ca11214902ce4/lib/python3.9/site-packages/urllib3/util/ssl_.py", line 449, in ssl_wrap_socket
    ssl_sock = _ssl_wrap_socket_impl(
  File "/Users/jelaleddin/anaconda3/envs/mlflow-d1fd4b13aac386abe6aa5a2ada1ca11214902ce4/lib/python3.9/site-packages/urllib3/util/ssl_.py", line 493, in _ssl_wrap_socket_impl
    return ssl_context.wrap_socket(sock, server_hostname=server_hostname)
  File "/Users/jelaleddin/anaconda3/envs/mlflow-d1fd4b13aac386abe6aa5a2ada1ca11214902ce4/lib/python3.9/ssl.py", line 500, in wrap_socket
    return self.sslsocket_class._create(
  File "/Users/jelaleddin/anaconda3/envs/mlflow-d1fd4b13aac386abe6aa5a2ada1ca11214902ce4/lib/python3.9/ssl.py", line 1040, in _create
    self.do_handshake()
  File "/Users/jelaleddin/anaconda3/envs/mlflow-d1fd4b13aac386abe6aa5a2ada1ca11214902ce4/lib/python3.9/ssl.py", line 1309, in do_handshake
    self._sslobj.do_handshake()
ConnectionResetError: [Errno 54] Connection reset by peer

During handling of the above exception, another exception occurred:

Traceback (most recent call last):
  File "/Users/jelaleddin/anaconda3/envs/mlflow-d1fd4b13aac386abe6aa5a2ada1ca11214902ce4/lib/python3.9/site-packages/requests/adapters.py", line 440, in send
    resp = conn.urlopen(
  File "/Users/jelaleddin/anaconda3/envs/mlflow-d1fd4b13aac386abe6aa5a2ada1ca11214902ce4/lib/python3.9/site-packages/urllib3/connectionpool.py", line 785, in urlopen
    retries = retries.increment(
  File "/Users/jelaleddin/anaconda3/envs/mlflow-d1fd4b13aac386abe6aa5a2ada1ca11214902ce4/lib/python3.9/site-packages/urllib3/util/retry.py", line 550, in increment
    raise six.reraise(type(error), error, _stacktrace)
  File "/Users/jelaleddin/anaconda3/envs/mlflow-d1fd4b13aac386abe6aa5a2ada1ca11214902ce4/lib/python3.9/site-packages/urllib3/packages/six.py", line 769, in reraise
    raise value.with_traceback(tb)
  File "/Users/jelaleddin/anaconda3/envs/mlflow-d1fd4b13aac386abe6aa5a2ada1ca11214902ce4/lib/python3.9/site-packages/urllib3/connectionpool.py", line 703, in urlopen
    httplib_response = self._make_request(
  File "/Users/jelaleddin/anaconda3/envs/mlflow-d1fd4b13aac386abe6aa5a2ada1ca11214902ce4/lib/python3.9/site-packages/urllib3/connectionpool.py", line 386, in _make_request
    self._validate_conn(conn)
  File "/Users/jelaleddin/anaconda3/envs/mlflow-d1fd4b13aac386abe6aa5a2ada1ca11214902ce4/lib/python3.9/site-packages/urllib3/connectionpool.py", line 1040, in _validate_conn
    conn.connect()
  File "/Users/jelaleddin/anaconda3/envs/mlflow-d1fd4b13aac386abe6aa5a2ada1ca11214902ce4/lib/python3.9/site-packages/urllib3/connection.py", line 416, in connect
    self.sock = ssl_wrap_socket(
  File "/Users/jelaleddin/anaconda3/envs/mlflow-d1fd4b13aac386abe6aa5a2ada1ca11214902ce4/lib/python3.9/site-packages/urllib3/util/ssl_.py", line 449, in ssl_wrap_socket
    ssl_sock = _ssl_wrap_socket_impl(
  File "/Users/jelaleddin/anaconda3/envs/mlflow-d1fd4b13aac386abe6aa5a2ada1ca11214902ce4/lib/python3.9/site-packages/urllib3/util/ssl_.py", line 493, in _ssl_wrap_socket_impl
    return ssl_context.wrap_socket(sock, server_hostname=server_hostname)
  File "/Users/jelaleddin/anaconda3/envs/mlflow-d1fd4b13aac386abe6aa5a2ada1ca11214902ce4/lib/python3.9/ssl.py", line 500, in wrap_socket
    return self.sslsocket_class._create(
  File "/Users/jelaleddin/anaconda3/envs/mlflow-d1fd4b13aac386abe6aa5a2ada1ca11214902ce4/lib/python3.9/ssl.py", line 1040, in _create
    self.do_handshake()
  File "/Users/jelaleddin/anaconda3/envs/mlflow-d1fd4b13aac386abe6aa5a2ada1ca11214902ce4/lib/python3.9/ssl.py", line 1309, in do_handshake
    self._sslobj.do_handshake()
urllib3.exceptions.ProtocolError: ('Connection aborted.', ConnectionResetError(54, 'Connection reset by peer'))

During handling of the above exception, another exception occurred:

Traceback (most recent call last):
  File "/Users/jelaleddin/anaconda3/envs/mlflow-d1fd4b13aac386abe6aa5a2ada1ca11214902ce4/lib/python3.9/site-packages/wandb/sdk/internal/internal_api.py", line 1198, in upload_file
    response = requests.put(url, data=progress, headers=extra_headers)
  File "/Users/jelaleddin/anaconda3/envs/mlflow-d1fd4b13aac386abe6aa5a2ada1ca11214902ce4/lib/python3.9/site-packages/requests/api.py", line 132, in put
    return request('put', url, data=data, **kwargs)
  File "/Users/jelaleddin/anaconda3/envs/mlflow-d1fd4b13aac386abe6aa5a2ada1ca11214902ce4/lib/python3.9/site-packages/requests/api.py", line 61, in request
    return session.request(method=method, url=url, **kwargs)
  File "/Users/jelaleddin/anaconda3/envs/mlflow-d1fd4b13aac386abe6aa5a2ada1ca11214902ce4/lib/python3.9/site-packages/requests/sessions.py", line 529, in request
    resp = self.send(prep, **send_kwargs)
  File "/Users/jelaleddin/anaconda3/envs/mlflow-d1fd4b13aac386abe6aa5a2ada1ca11214902ce4/lib/python3.9/site-packages/requests/sessions.py", line 645, in send
    r = adapter.send(request, **kwargs)
  File "/Users/jelaleddin/anaconda3/envs/mlflow-d1fd4b13aac386abe6aa5a2ada1ca11214902ce4/lib/python3.9/site-packages/requests/adapters.py", line 501, in send
    raise ConnectionError(err, request=request)
requests.exceptions.ConnectionError: ('Connection aborted.', ConnectionResetError(54, 'Connection reset by peer'))

During handling of the above exception, another exception occurred:

Traceback (most recent call last):
  File "/Users/jelaleddin/anaconda3/envs/mlflow-d1fd4b13aac386abe6aa5a2ada1ca11214902ce4/lib/python3.9/site-packages/wandb/old/retry.py", line 96, in __call__
    result = self._call_fn(*args, **kwargs)
  File "/Users/jelaleddin/anaconda3/envs/mlflow-d1fd4b13aac386abe6aa5a2ada1ca11214902ce4/lib/python3.9/site-packages/wandb/sdk/internal/internal_api.py", line 1209, in upload_file
    util.sentry_reraise(retry.TransientException(exc=e))
  File "/Users/jelaleddin/anaconda3/envs/mlflow-d1fd4b13aac386abe6aa5a2ada1ca11214902ce4/lib/python3.9/site-packages/wandb/util.py", line 120, in sentry_reraise
    six.reraise(type(exc), exc, sys.exc_info()[2])
  File "/Users/jelaleddin/anaconda3/envs/mlflow-d1fd4b13aac386abe6aa5a2ada1ca11214902ce4/lib/python3.9/site-packages/six.py", line 718, in reraise
    raise value.with_traceback(tb)
  File "/Users/jelaleddin/anaconda3/envs/mlflow-d1fd4b13aac386abe6aa5a2ada1ca11214902ce4/lib/python3.9/site-packages/wandb/sdk/internal/internal_api.py", line 1198, in upload_file
    response = requests.put(url, data=progress, headers=extra_headers)
  File "/Users/jelaleddin/anaconda3/envs/mlflow-d1fd4b13aac386abe6aa5a2ada1ca11214902ce4/lib/python3.9/site-packages/requests/api.py", line 132, in put
    return request('put', url, data=data, **kwargs)
  File "/Users/jelaleddin/anaconda3/envs/mlflow-d1fd4b13aac386abe6aa5a2ada1ca11214902ce4/lib/python3.9/site-packages/requests/api.py", line 61, in request
    return session.request(method=method, url=url, **kwargs)
  File "/Users/jelaleddin/anaconda3/envs/mlflow-d1fd4b13aac386abe6aa5a2ada1ca11214902ce4/lib/python3.9/site-packages/requests/sessions.py", line 529, in request
    resp = self.send(prep, **send_kwargs)
  File "/Users/jelaleddin/anaconda3/envs/mlflow-d1fd4b13aac386abe6aa5a2ada1ca11214902ce4/lib/python3.9/site-packages/requests/sessions.py", line 645, in send
    r = adapter.send(request, **kwargs)
  File "/Users/jelaleddin/anaconda3/envs/mlflow-d1fd4b13aac386abe6aa5a2ada1ca11214902ce4/lib/python3.9/site-packages/requests/adapters.py", line 501, in send
    raise ConnectionError(err, request=request)
wandb.old.retry.TransientException: None
2022-02-24 15:11:46,463 ERROR   Thread-10 :28593 [internal_api.py:upload_file():1201] upload_file exception https://storage.googleapis.com/wandb-production.appspot.com/jelal/telco_churn/376tdk7x/config.yaml?Expires=1645783897&GoogleAccessId=wandb-production%40appspot.gserviceaccount.com&Signature=jtSgfvx%2B2hwQ%2Bl7cRCFeB0%2BpKbZubUSwPXdKVdWnZj8IpJuK5gGmtCcb2l1N5qDXq6ivj8M7qw%2BNNS%2BRl8MIo%2F0DQbx31w%2FvI0SRzeZEtVWDRtH39JxIz4xha%2FLnmAoIw6aCI8SgMumjJ0Ex1gFBpeDT6kKFwS8NTYrPBLOpX0amnKorQ4clgOZrZKKlz4w3ZKAnjDDFKkjQHHzkHDju3M1ttZGGS0vA%2FJyyY%2FISe607lPqqvl0j%2B%2B4NQ3S8DmfSeNQ5gdRF5D7KpauhpSjQWxj36CCzCk7nes3WM7cfG%2FJNeOnNP378WyFgynW2Fl74r3L29sKNq0BHyRGaqZAwHw%3D%3D ('Connection aborted.', ConnectionResetError(54, 'Connection reset by peer'))
2022-02-24 15:11:58,179 INFO    MainThread:28593 [internal.py:handle_exit():78] Internal process exited
