
2022-02-17 15:36:47,580 Fetching artifact clean_telco.csv:latest
Traceback (most recent call last):
  File "/Users/jelaleddin/anaconda3/envs/mlflow-e22e9996835c795d42db199b2d7a286b1ecc7894/lib/python3.9/site-packages/urllib3/connectionpool.py", line 670, in urlopen
    httplib_response = self._make_request(
  File "/Users/jelaleddin/anaconda3/envs/mlflow-e22e9996835c795d42db199b2d7a286b1ecc7894/lib/python3.9/site-packages/urllib3/connectionpool.py", line 381, in _make_request
    self._validate_conn(conn)
  File "/Users/jelaleddin/anaconda3/envs/mlflow-e22e9996835c795d42db199b2d7a286b1ecc7894/lib/python3.9/site-packages/urllib3/connectionpool.py", line 978, in _validate_conn
    conn.connect()
  File "/Users/jelaleddin/anaconda3/envs/mlflow-e22e9996835c795d42db199b2d7a286b1ecc7894/lib/python3.9/site-packages/urllib3/connection.py", line 362, in connect
    self.sock = ssl_wrap_socket(
  File "/Users/jelaleddin/anaconda3/envs/mlflow-e22e9996835c795d42db199b2d7a286b1ecc7894/lib/python3.9/site-packages/urllib3/util/ssl_.py", line 386, in ssl_wrap_socket
    return context.wrap_socket(sock, server_hostname=server_hostname)
  File "/Users/jelaleddin/anaconda3/envs/mlflow-e22e9996835c795d42db199b2d7a286b1ecc7894/lib/python3.9/ssl.py", line 500, in wrap_socket
    return self.sslsocket_class._create(
  File "/Users/jelaleddin/anaconda3/envs/mlflow-e22e9996835c795d42db199b2d7a286b1ecc7894/lib/python3.9/ssl.py", line 1040, in _create
    self.do_handshake()
  File "/Users/jelaleddin/anaconda3/envs/mlflow-e22e9996835c795d42db199b2d7a286b1ecc7894/lib/python3.9/ssl.py", line 1309, in do_handshake
    self._sslobj.do_handshake()
ConnectionResetError: [Errno 54] Connection reset by peer
During handling of the above exception, another exception occurred:
Traceback (most recent call last):
  File "/Users/jelaleddin/anaconda3/envs/mlflow-e22e9996835c795d42db199b2d7a286b1ecc7894/lib/python3.9/site-packages/requests/adapters.py", line 439, in send
    resp = conn.urlopen(
  File "/Users/jelaleddin/anaconda3/envs/mlflow-e22e9996835c795d42db199b2d7a286b1ecc7894/lib/python3.9/site-packages/urllib3/connectionpool.py", line 726, in urlopen
    retries = retries.increment(
  File "/Users/jelaleddin/anaconda3/envs/mlflow-e22e9996835c795d42db199b2d7a286b1ecc7894/lib/python3.9/site-packages/urllib3/util/retry.py", line 410, in increment
    raise six.reraise(type(error), error, _stacktrace)
  File "/Users/jelaleddin/anaconda3/envs/mlflow-e22e9996835c795d42db199b2d7a286b1ecc7894/lib/python3.9/site-packages/urllib3/packages/six.py", line 734, in reraise
    raise value.with_traceback(tb)
  File "/Users/jelaleddin/anaconda3/envs/mlflow-e22e9996835c795d42db199b2d7a286b1ecc7894/lib/python3.9/site-packages/urllib3/connectionpool.py", line 670, in urlopen
    httplib_response = self._make_request(
  File "/Users/jelaleddin/anaconda3/envs/mlflow-e22e9996835c795d42db199b2d7a286b1ecc7894/lib/python3.9/site-packages/urllib3/connectionpool.py", line 381, in _make_request
    self._validate_conn(conn)
  File "/Users/jelaleddin/anaconda3/envs/mlflow-e22e9996835c795d42db199b2d7a286b1ecc7894/lib/python3.9/site-packages/urllib3/connectionpool.py", line 978, in _validate_conn
    conn.connect()
  File "/Users/jelaleddin/anaconda3/envs/mlflow-e22e9996835c795d42db199b2d7a286b1ecc7894/lib/python3.9/site-packages/urllib3/connection.py", line 362, in connect
    self.sock = ssl_wrap_socket(
  File "/Users/jelaleddin/anaconda3/envs/mlflow-e22e9996835c795d42db199b2d7a286b1ecc7894/lib/python3.9/site-packages/urllib3/util/ssl_.py", line 386, in ssl_wrap_socket
    return context.wrap_socket(sock, server_hostname=server_hostname)
  File "/Users/jelaleddin/anaconda3/envs/mlflow-e22e9996835c795d42db199b2d7a286b1ecc7894/lib/python3.9/ssl.py", line 500, in wrap_socket
    return self.sslsocket_class._create(
  File "/Users/jelaleddin/anaconda3/envs/mlflow-e22e9996835c795d42db199b2d7a286b1ecc7894/lib/python3.9/ssl.py", line 1040, in _create
    self.do_handshake()
  File "/Users/jelaleddin/anaconda3/envs/mlflow-e22e9996835c795d42db199b2d7a286b1ecc7894/lib/python3.9/ssl.py", line 1309, in do_handshake
    self._sslobj.do_handshake()
urllib3.exceptions.ProtocolError: ('Connection aborted.', ConnectionResetError(54, 'Connection reset by peer'))
During handling of the above exception, another exception occurred:
Traceback (most recent call last):
  File "/Users/jelaleddin/MLPipeline-TelcoCustomerChurn/components/train_val_test_split/run.py", line 67, in <module>
    go(args)
  File "/Users/jelaleddin/MLPipeline-TelcoCustomerChurn/components/train_val_test_split/run.py", line 22, in go
    artifact_local_path = run.use_artifact(args.input).file()
  File "/Users/jelaleddin/anaconda3/envs/mlflow-e22e9996835c795d42db199b2d7a286b1ecc7894/lib/python3.9/site-packages/wandb/apis/public.py", line 3127, in file
    manifest = self._load_manifest()
  File "/Users/jelaleddin/anaconda3/envs/mlflow-e22e9996835c795d42db199b2d7a286b1ecc7894/lib/python3.9/site-packages/wandb/apis/public.py", line 3289, in _load_manifest
    with requests.get(index_file_url) as req:
  File "/Users/jelaleddin/anaconda3/envs/mlflow-e22e9996835c795d42db199b2d7a286b1ecc7894/lib/python3.9/site-packages/requests/api.py", line 76, in get
    return request('get', url, params=params, **kwargs)
  File "/Users/jelaleddin/anaconda3/envs/mlflow-e22e9996835c795d42db199b2d7a286b1ecc7894/lib/python3.9/site-packages/requests/api.py", line 61, in request
    return session.request(method=method, url=url, **kwargs)
  File "/Users/jelaleddin/anaconda3/envs/mlflow-e22e9996835c795d42db199b2d7a286b1ecc7894/lib/python3.9/site-packages/requests/sessions.py", line 530, in request
    resp = self.send(prep, **send_kwargs)
  File "/Users/jelaleddin/anaconda3/envs/mlflow-e22e9996835c795d42db199b2d7a286b1ecc7894/lib/python3.9/site-packages/requests/sessions.py", line 643, in send
    r = adapter.send(request, **kwargs)
  File "/Users/jelaleddin/anaconda3/envs/mlflow-e22e9996835c795d42db199b2d7a286b1ecc7894/lib/python3.9/site-packages/requests/adapters.py", line 498, in send
    raise ConnectionError(err, request=request)
requests.exceptions.ConnectionError: ('Connection aborted.', ConnectionResetError(54, 'Connection reset by peer'))