[34m[1mwandb[39m[22m: [32m[41mERROR[39m[49m Project jelal/uncategorized does not contain artifact: "clean_telco.csv:latest"
Traceback (most recent call last):
  File "/Users/jelaleddin/anaconda3/envs/telco_env/lib/python3.8/site-packages/wandb/apis/normalize.py", line 24, in wrapper
    return func(*args, **kwargs)
  File "/Users/jelaleddin/anaconda3/envs/telco_env/lib/python3.8/site-packages/wandb/apis/public.py", line 557, in artifact
    artifact = Artifact(self.client, entity, project, artifact_name)
  File "/Users/jelaleddin/anaconda3/envs/telco_env/lib/python3.8/site-packages/wandb/apis/public.py", line 2759, in __init__
    self._load()
  File "/Users/jelaleddin/anaconda3/envs/telco_env/lib/python3.8/site-packages/wandb/apis/public.py", line 3243, in _load
    raise ValueError(
ValueError: Project jelal/uncategorized does not contain artifact: "clean_telco.csv:latest"
During handling of the above exception, another exception occurred:
Traceback (most recent call last):
  File "/Users/jelaleddin/MLPipeline-TelcoCustomerChurn/test1.py", line 14, in <module>
    data_path = run.use_artifact('clean_telco.csv:latest').file()
  File "/Users/jelaleddin/anaconda3/envs/telco_env/lib/python3.8/site-packages/wandb/sdk/wandb_run.py", line 2021, in use_artifact
    artifact = public_api.artifact(type=type, name=name)
  File "/Users/jelaleddin/anaconda3/envs/telco_env/lib/python3.8/site-packages/wandb/apis/normalize.py", line 62, in wrapper
    six.reraise(CommError, CommError(message, err), sys.exc_info()[2])
  File "/Users/jelaleddin/anaconda3/envs/telco_env/lib/python3.8/site-packages/six.py", line 718, in reraise
    raise value.with_traceback(tb)
  File "/Users/jelaleddin/anaconda3/envs/telco_env/lib/python3.8/site-packages/wandb/apis/normalize.py", line 24, in wrapper
    return func(*args, **kwargs)
  File "/Users/jelaleddin/anaconda3/envs/telco_env/lib/python3.8/site-packages/wandb/apis/public.py", line 557, in artifact
    artifact = Artifact(self.client, entity, project, artifact_name)
  File "/Users/jelaleddin/anaconda3/envs/telco_env/lib/python3.8/site-packages/wandb/apis/public.py", line 2759, in __init__
    self._load()
  File "/Users/jelaleddin/anaconda3/envs/telco_env/lib/python3.8/site-packages/wandb/apis/public.py", line 3243, in _load
    raise ValueError(
wandb.errors.CommError: Project jelal/uncategorized does not contain artifact: "clean_telco.csv:latest"